2021-10-04 22:16:57,545 - instabot version: 0.117.0 (bot) - INFO - Instabot version: 0.117.0 Started
2021-10-04 22:16:57,547 - instabot version: 0.117.0 (bot) - DEBUG - Bot imported from C:\Users\lenovo\AppData\Local\Programs\Python\Python38\lib\site-packages\instabot\bot\bot.py
2021-10-04 22:16:57,549 - instabot version: 0.117.0 (api_login) - INFO - Not yet logged in starting: PRE-LOGIN FLOW!
2021-10-04 22:16:59,909 - instabot version: 0.117.0 (api) - WARNING - HTTPSConnectionPool(host='i.instagram.com', port=443): Max retries exceeded with url: /api/v1/accounts/get_prefill_candidates/ (Caused by NewConnectionError('<urllib3.connection.HTTPSConnection object at 0x00000039CAC05580>: Failed to establish a new connection: [Errno 11002] getaddrinfo failed'))
2021-10-04 22:17:03,048 - instabot version: 0.117.0 (api) - WARNING - HTTPSConnectionPool(host='i.instagram.com', port=443): Max retries exceeded with url: /api/v1/qe/sync/ (Caused by NewConnectionError('<urllib3.connection.HTTPSConnection object at 0x00000039CAC055E0>: Failed to establish a new connection: [Errno 11002] getaddrinfo failed'))
2021-10-04 22:17:07,880 - instabot version: 0.117.0 (api) - WARNING - HTTPSConnectionPool(host='i.instagram.com', port=443): Max retries exceeded with url: /api/v1/launcher/sync/ (Caused by NewConnectionError('<urllib3.connection.HTTPSConnection object at 0x00000039CAC05610>: Failed to establish a new connection: [Errno 11002] getaddrinfo failed'))
2021-10-04 22:17:11,927 - instabot version: 0.117.0 (api) - WARNING - HTTPSConnectionPool(host='i.instagram.com', port=443): Max retries exceeded with url: /api/v1/accounts/contact_point_prefill/ (Caused by NewConnectionError('<urllib3.connection.HTTPSConnection object at 0x00000039CAC055E0>: Failed to establish a new connection: [Errno 11002] getaddrinfo failed'))
